Workbook

Sheet 📊 Dashboard
A1: 📊 FREELANCER FINANCE DASHBOARD
A4: ='⚙ Settings'!C5&" | Updated live as you enter data in each sheet" -> Jane Doe Creative | Updated live as you enter data in each sheet
B6: YOUR MONEY AT A GLANCE
B7: TOTAL EARNED | D7: SET ASIDE FOR TAX | F7: YOURS TO KEEP
B8: ='💰 Income Log'!F64 -> 25200 | D8: ='💰 Income Log'!G64 -> 3855.6 | F8: ='💰 Income Log'!F64-'💸 Expenses'!F64-'💰 Income Log'!G64 -> 20178.51
B10: TOTAL EXPENSES | D10: PROFIT MARGIN | F10: INVOICES OVERDUE | H10: OUTSTANDING A/R
B11: ='💸 Expenses'!F64 -> 1165.89 | D11: =IFERROR(('💰 Income Log'!F64-'💸 Expenses'!F64)/'💰 Income Log'!F64,0) -> 0.95373452 | F11: =COUNTIF('🧾 Invoices'!H5:H53,"Overdue") -> 1 | H11: =SUMIF('🧾 Invoices'!H5:H53,"<>Paid",'🧾 Invoices'!F5:F53) -> 9700
B13: MONTHLY GOAL | D13: THIS MONTH INCOME | F13: EST. TAX DUE | H13: SAFE TO PAY SELF
B14: ='⚙ Settings'!C15 -> 0 | D14: =SUMPRODUCT((MONTH('💰 Income Log'!A5:A63)=MONTH(TODAY()))*('💰 Income Log'!F5:F63)) -> 7500 | F14: ='🧮 Tax Tracker'!B23 -> 0 | H14: =IFERROR('🧮 Tax Tracker'!B29/12,0) -> 108.14452
B17: MONTHLY BREAKDOWN
B18: Month | C18: Income | D18: Expenses | E18: Net Profit | F18: Margin | G18: Running Net | H18: vs Goal
B19: January | C19: =SUMPRODUCT((MONTH('💰 Income Log'!A5:A63)=1)*('💰 Income Log'!F5:F63)) -> 9700 | D19: =SUMPRODUCT((MONTH('💸 Expenses'!A5:A63)=1)*('💸 Expenses'!F5:F63)) -> 492.42 | E19: =C19-D19 -> 9207.58 | F19: =IFERROR(E19/C19,0) -> 0.94923505 | G19: =E19 -> 9207.58 | H19: =C19-'⚙ Settings'!C15 -> 9700
B20: February | C20: =SUMPRODUCT((MONTH('💰 Income Log'!A5:A63)=2)*('💰 Income Log'!F5:F63)) -> 8000 | D20: =SUMPRODUCT((MONTH('💸 Expenses'!A5:A63)=2)*('💸 Expenses'!F5:F63)) -> 439.49 | E20: =C20-D20 -> 7560.51 | F20: =IFERROR(E20/C20,0) -> 0.94506375 | G20: =G19+E20 -> 16768.09 | H20: =C20-'⚙ Settings'!C15 -> 8000
B21: March | C21: =SUMPRODUCT((MONTH('💰 Income Log'!A5:A63)=3)*('💰 Income Log'!F5:F63)) -> 7500 | D21: =SUMPRODUCT((MONTH('💸 Expenses'!A5:A63)=3)*('💸 Expenses'!F5:F63)) -> 233.98 | E21: =C21-D21 -> 7266.02 | F21: =IFERROR(E21/C21,0) -> 0.96880267 | G21: =G20+E21 -> 24034.11 | H21: =C21-'⚙ Settings'!C15 -> 7500
B22: April | C22: =SUMPRODUCT((MONTH('💰 Income Log'!A5:A63)=4)*('💰 Income Log'!F5:F63)) -> 0 | D22: =SUMPRODUCT((MONTH('💸 Expenses'!A5:A63)=4)*('💸 Expenses'!F5:F63)) -> 0 | E22: =C22-D22 -> 0 | F22: =IFERROR(E22/C22,0) -> 0 | G22: =G21+E22 -> 24034.11 | H22: =C22-'⚙ Settings'!C15 -> 0
B23: May | C23: =SUMPRODUCT((MONTH('💰 Income Log'!A5:A63)=5)*('💰 Income Log'!F5:F63)) -> 0 | D23: =SUMPRODUCT((MONTH('💸 Expenses'!A5:A63)=5)*('💸 Expenses'!F5:F63)) -> 0 | E23: =C23-D23 -> 0 | F23: =IFERROR(E23/C23,0) -> 0 | G23: =G22+E23 -> 24034.11 | H23: =C23-'⚙ Settings'!C15 -> 0
B24: June | C24: =SUMPRODUCT((MONTH('💰 Income Log'!A5:A63)=6)*('💰 Income Log'!F5:F63)) -> 0 | D24: =SUMPRODUCT((MONTH('💸 Expenses'!A5:A63)=6)*('💸 Expenses'!F5:F63)) -> 0 | E24: =C24-D24 -> 0 | F24: =IFERROR(E24/C24,0) -> 0 | G24: =G23+E24 -> 24034.11 | H24: =C24-'⚙ Settings'!C15 -> 0
B25: July | C25: =SUMPRODUCT((MONTH('💰 Income Log'!A5:A63)=7)*('💰 Income Log'!F5:F63)) -> 0 | D25: =SUMPRODUCT((MONTH('💸 Expenses'!A5:A63)=7)*('💸 Expenses'!F5:F63)) -> 0 | E25: =C25-D25 -> 0 | F25: =IFERROR(E25/C25,0) -> 0 | G25: =G24+E25 -> 24034.11 | H25: =C25-'⚙ Settings'!C15 -> 0
B26: August | C26: =SUMPRODUCT((MONTH('💰 Income Log'!A5:A63)=8)*('💰 Income Log'!F5:F63)) -> 0 | D26: =SUMPRODUCT((MONTH('💸 Expenses'!A5:A63)=8)*('💸 Expenses'!F5:F63)) -> 0 | E26: =C26-D26 -> 0 | F26: =IFERROR(E26/C26,0) -> 0 | G26: =G25+E26 -> 24034.11 | H26: =C26-'⚙ Settings'!C15 -> 0
B27: September | C27: =SUMPRODUCT((MONTH('💰 Income Log'!A5:A63)=9)*('💰 Income Log'!F5:F63)) -> 0 | D27: =SUMPRODUCT((MONTH('💸 Expenses'!A5:A63)=9)*('💸 Expenses'!F5:F63)) -> 0 | E27: =C27-D27 -> 0 | F27: =IFERROR(E27/C27,0) -> 0 | G27: =G26+E27 -> 24034.11 | H27: =C27-'⚙ Settings'!C15 -> 0
B28: October | C28: =SUMPRODUCT((MONTH('💰 Income Log'!A5:A63)=10)*('💰 Income Log'!F5:F63)) -> 0 | D28: =SUMPRODUCT((MONTH('💸 Expenses'!A5:A63)=10)*('💸 Expenses'!F5:F63)) -> 0 | E28: =C28-D28 -> 0 | F28: =IFERROR(E28/C28,0) -> 0 | G28: =G27+E28 -> 24034.11 | H28: =C28-'⚙ Settings'!C15 -> 0
B29: November | C29: =SUMPRODUCT((MONTH('💰 Income Log'!A5:A63)=11)*('💰 Income Log'!F5:F63)) -> 0 | D29: =SUMPRODUCT((MONTH('💸 Expenses'!A5:A63)=11)*('💸 Expenses'!F5:F63)) -> 0 | E29: =C29-D29 -> 0 | F29: =IFERROR(E29/C29,0) -> 0 | G29: =G28+E29 -> 24034.11 | H29: =C29-'⚙ Settings'!C15 -> 0
B30: December | C30: =SUMPRODUCT((MONTH('💰 Income Log'!A5:A63)=12)*('💰 Income Log'!F5:F63)) -> 0 | D30: =SUMPRODUCT((MONTH('💸 Expenses'!A5:A63)=12)*('💸 Expenses'!F5:F63)) -> 0 | E30: =C30-D30 -> 0 | F30: =IFERROR(E30/C30,0) -> 0 | G30: =G29+E30 -> 24034.11 | H30: =C30-'⚙ Settings'!C15 -> 0
B31: ANNUAL TOTAL | C31: =SUM(C19:C30) -> 25200 | D31: =SUM(D19:D30) -> 1165.89 | E31: =SUM(E19:E30) -> 24034.11 | F31: =IFERROR(E31/C31,0) -> 0.95373452 | G31: =G30 -> 24034.11 | H31: =SUM(H19:H30) -> 25200
B33: 📋 NAVIGATION GUIDE
B34: ⚙ Settings | D34: Start here. Set your tax rates, goals, and business info.
B35: 💰 Income Log | D35: Log every payment. Tax set-aside auto-fills col G.
B36: 💸 Expenses | D36: Track expenses. Mark deductible items to reduce taxes.
B37: 🚗 Mileage & Home Office | D37: Log business miles + home office for hidden deductions.
B38: 🧾 Invoices | D38: Track all invoices. See aging buckets to chase late payments.
B39: 🧮 Tax Tracker | D39: See what you owe. Enter quarterly payments made.
B40: 👥 Client Report | D40: See which clients generate the most revenue + 1099 alerts.
B41: 💡 Rate Calculator | D41: Calculate your minimum hourly/project rate to hit your goals.

Sheet ⚙ Settings
A1: ⚙ SETTINGS — Fill Yellow Cells First
A3: These values power every formula in the workbook.
B4: BUSINESS INFO
B5: Your Name / Business Name | C5: Jane Doe Creative
B6: Business Type | C6: Sole Proprietor
B7: Tax Year | C7: 2026
B8: Currency | C8: USD
B10: TAX RATES
B11: Federal Income Tax Rate | C11: 0.22
B12: State Income Tax Rate | C12: 0.08
B13: Self-Employment Tax Rate | C13: 0.153
B14: Tax Set-Aside % (per payment) | C14: 0.3
B16: GOALS
B17: Monthly Revenue Goal | C17: 10000
B18: Monthly Expense Budget | C18: 2500
B19: Target Annual Take-Home | C19: 72000
B20: Target Billable Hours/Week | C20: 30
B22: INVOICE SETTINGS
B23: Default Payment Terms (days) | C23: 30
B24: 1099 Threshold ($) | C24: 600
B26: HOME OFFICE
B27: Home Office Sq Ft | C27: 200
B28: Total Home Sq Ft | C28: 1200
B29: Monthly Rent/Mortgage | C29: 2500
B30: Monthly Utilities | C30: 150

Sheet 💰 Income Log
A1: 💰 INCOME LOG
A3: Log every payment. Tax set-aside auto-calculates. 1099 alert triggers at $600 per client.
A4: Date | B4: Client | C4: Project / Description | D4: Category | E4: Invoice # | F4: Amount ($) | G4: Set Aside (Tax) | H4: Payment Method | I4: Notes
A5: 2026-01-05 | B5: Acme Corp | C5: Brand Identity Design | D5: Design | E5: INV-001 | F5: 3500 | G5: =F5*'⚙ Settings'!C13 -> 535.5 | H5: Bank Transfer
A6: 2026-01-12 | B6: Beta Startup | C6: Website Development | D6: Development | E6: INV-002 | F6: 5000 | G6: =F6*'⚙ Settings'!C13 -> 765 | H6: PayPal | I6: 50% deposit
A7: 2026-01-20 | B7: Gamma LLC | C7: SEO Consulting | D7: Consulting | E7: INV-003 | F7: 1200 | G7: =F7*'⚙ Settings'!C13 -> 183.6 | H7: Check
A8: 2026-02-03 | B8: Acme Corp | C8: Logo Revisions | D8: Design | E8: INV-004 | F8: 800 | G8: =F8*'⚙ Settings'!C13 -> 122.4 | H8: Bank Transfer
A9: 2026-02-14 | B9: Delta Media | C9: Social Media Strategy | D9: Consulting | E9: INV-005 | F9: 2200 | G9: =F9*'⚙ Settings'!C13 -> 336.6 | H9: Stripe
A10: 2026-02-28 | B10: Beta Startup | C10: Website Dev Phase 2 | D10: Development | E10: INV-006 | F10: 5000 | G10: =F10*'⚙ Settings'!C13 -> 765 | H10: PayPal | I10: Final payment
A11: 2026-03-05 | B11: Epsilon Co | C11: Copywriting Package | D11: Writing | E11: INV-007 | F11: 1800 | G11: =F11*'⚙ Settings'!C13 -> 275.4 | H11: Bank Transfer
A12: 2026-03-18 | B12: Gamma LLC | C12: SEO Consulting Mar | D12: Consulting | E12: INV-008 | F12: 1200 | G12: =F12*'⚙ Settings'!C13 -> 183.6 | H12: Check
A13: 2026-03-25 | B13: Zeta Brands | C13: Marketing Campaign | D13: Marketing | E13: INV-009 | F13: 4500 | G13: =F13*'⚙ Settings'!C13 -> 688.5 | H13: Stripe
G14: =IF(F14="","",F14*'⚙ Settings'!C13)
G15: =IF(F15="","",F15*'⚙ Settings'!C13)
G16: =IF(F16="","",F16*'⚙ Settings'!C13)
G17: =IF(F17="","",F17*'⚙ Settings'!C13)
G18: =IF(F18="","",F18*'⚙ Settings'!C13)
G19: =IF(F19="","",F19*'⚙ Settings'!C13)
G20: =IF(F20="","",F20*'⚙ Settings'!C13)
G21: =IF(F21="","",F21*'⚙ Settings'!C13)
G22: =IF(F22="","",F22*'⚙ Settings'!C13)
G23: =IF(F23="","",F23*'⚙ Settings'!C13)
G24: =IF(F24="","",F24*'⚙ Settings'!C13)
G25: =IF(F25="","",F25*'⚙ Settings'!C13)
G26: =IF(F26="","",F26*'⚙ Settings'!C13)
G27: =IF(F27="","",F27*'⚙ Settings'!C13)
G28: =IF(F28="","",F28*'⚙ Settings'!C13)
G29: =IF(F29="","",F29*'⚙ Settings'!C13)
G30: =IF(F30="","",F30*'⚙ Settings'!C13)
G31: =IF(F31="","",F31*'⚙ Settings'!C13)
G32: =IF(F32="","",F32*'⚙ Settings'!C13)
G33: =IF(F33="","",F33*'⚙ Settings'!C13)
G34: =IF(F34="","",F34*'⚙ Settings'!C13)
G35: =IF(F35="","",F35*'⚙ Settings'!C13)
G36: =IF(F36="","",F36*'⚙ Settings'!C13)
G37: =IF(F37="","",F37*'⚙ Settings'!C13)
G38: =IF(F38="","",F38*'⚙ Settings'!C13)
G39: =IF(F39="","",F39*'⚙ Settings'!C13)
G40: =IF(F40="","",F40*'⚙ Settings'!C13)
G41: =IF(F41="","",F41*'⚙ Settings'!C13)
...

Sheet 💸 Expenses
A1: 💸 EXPENSE TRACKER
A3: Track every business expense. Tax-deductible items reduce your taxable income.
A4: Date | B4: Vendor | C4: Description | D4: Category | E4: Receipt # | F4: Amount ($) | G4: Deductible? | H4: Notes
A5: 2026-01-02 | B5: Adobe Inc | C5: Creative Cloud | D5: Software | E5: RCP-001 | F5: 54.99 | G5: Yes
A6: 2026-01-08 | B6: WeWork | C6: Co-working Jan | D6: Office | E6: RCP-002 | F6: 350 | G6: Yes
A7: 2026-01-15 | B7: Amazon | C7: Office Supplies | D7: Supplies | E7: RCP-003 | F7: 87.43 | G7: Yes
A8: 2026-02-01 | B8: Adobe Inc | C8: Creative Cloud | D8: Software | E8: RCP-004 | F8: 54.99 | G8: Yes
A9: 2026-02-08 | B9: WeWork | C9: Co-working Feb | D9: Office | E9: RCP-005 | F9: 350 | G9: Yes
A10: 2026-02-20 | B10: Uber | C10: Client Meeting | D10: Travel | E10: RCP-006 | F10: 34.5 | G10: Yes
A11: 2026-03-01 | B11: Adobe Inc | C11: Creative Cloud | D11: Software | E11: RCP-007 | F11: 54.99 | G11: Yes
A12: 2026-03-10 | B12: Best Buy | C12: External Drive | D12: Equipment | E12: RCP-008 | F12: 129.99 | G12: Yes
A13: 2026-03-22 | B13: Mailchimp | C13: Email Marketing | D13: Marketing | E13: RCP-009 | F13: 49 | G13: Yes
A64: TOTAL EXPENSES | F64: =SUM(F5:F63) -> 1165.89
A65: DEDUCTIBLE TOTAL (reduces taxable income) | F65: =SUMIF(G5:G63,"Yes",F5:F63) -> 1165.89

Sheet 🚗 Mileage & Home Office
A1: 🚗 MILEAGE & HOME OFFICE DEDUCTIONS
A3: Two of the most missed deductions. Auto-calculates your annual deduction.
A4: MILEAGE LOG (IRS Standard Rate auto-applied)
A6: Date | B6: Purpose / Destination | C6: From | D6: To | E6: Miles | F6: Rate ($/mi) | G6: Deduction ($)
A7: 2026-01-10 | B7: Client Meeting — Acme Corp | C7: Home | D7: Acme Office | E7: 18.4 | F7: 0.67 | G7: =E7*F7 -> 12.328
A8: 2026-01-22 | B8: Office Supply Run | C8: Home | D8: Staples | E8: 6.2 | F8: 0.67 | G8: =E8*F8 -> 4.154
A9: 2026-02-05 | B9: Networking Event | C9: Home | D9: Downtown Convention | E9: 24 | F9: 0.67 | G9: =E9*F9 -> 16.08
A10: 2026-02-18 | B10: Client Presentation — Beta | C10: Home | D10: Beta HQ | E10: 31.5 | F10: 0.67 | G10: =E10*F10 -> 21.105
A11: 2026-03-12 | B11: Post Office — Invoice Docs | C11: Home | D11: USPS | E11: 3.1 | F11: 0.67 | G11: =E11*F11 -> 2.077
F12: 0.67 | G12: =IF(E12="","",E12*F12)
F13: 0.67 | G13: =IF(E13="","",E13*F13)
F14: 0.67 | G14: =IF(E14="","",E14*F14)
F15: 0.67 | G15: =IF(E15="","",E15*F15)
F16: 0.67 | G16: =IF(E16="","",E16*F16)
F17: 0.67 | G17: =IF(E17="","",E17*F17)
F18: 0.67 | G18: =IF(E18="","",E18*F18)
F19: 0.67 | G19: =IF(E19="","",E19*F19)
F20: 0.67 | G20: =IF(E20="","",E20*F20)
F21: 0.67 | G21: =IF(E21="","",E21*F21)
F22: 0.67 | G22: =IF(E22="","",E22*F22)
F23: 0.67 | G23: =IF(E23="","",E23*F23)
... F51: 0.67 | G51: =IF(E51="","",E51*F51)
A52: TOTAL MILEAGE DEDUCTION | E52: =SUM(E7:E51) -> 83.2 | G52: =SUM(G7:G51) -> 55.744
A54: HOME OFFICE DEDUCTION (Simplified Method)
A56: Home Office Sq Ft | E56: ='⚙ Settings'!C27 -> 200
A57: Total Home Sq Ft | E57: ='⚙ Settings'!C28 -> 1200
A58: Business Use % | E58: =IFERROR(E56/E57,0) -> 0.16666667
A59: Monthly Rent/Mortgage | E59: ='⚙ Settings'!C29 -> 2500
A60: Monthly Utilities | E60: ='⚙ Settings'!C30 -> 150
A61: Annual Home Costs | E61: =(E59+E60)*12 -> 31800
A62: HOME OFFICE DEDUCTION | E62: =E58*E61 -> 5300

Sheet 🧾 Invoices
A1: 🧾 INVOICE TRACKER
A3: Status auto-highlights. Aging buckets show cash flow health at a glance.
A4: Invoice # | B4: Client | C4: Description | D4: Issue Date | E4: Due Date | F4: Amount ($) | G4: Paid Date | H4: Status | I4: Days Overdue
A5: INV-001 | B5: Acme Corp | C5: Brand Identity | D5: 2026-01-01 | E5: 2026-01-31 | F5: 3500 | G5: 2026-01-28 | H5: Paid | I5: =IF(H5="Paid","✓",IF(E5="","",IF(TODAY()>E5,TODAY()-E5,"On time"))) -> ✓
A6: INV-002 | B6: Beta Startup | C6: Website Dev | D6: 2026-01-10 | E6: 2026-02-09 | F6: 5000 | G6: 2026-02-05 | H6: Paid | I6: =IF(H6="Paid","✓",IF(E6="","",IF(TODAY()>E6,TODAY()-E6,"On time"))) -> ✓
A7: INV-003 | B7: Gamma LLC | C7: SEO Jan | D7: 2026-01-15 | E7: 2026-02-14 | F7: 1200 | G7: 2026-02-20 | H7: Paid | I7: =IF(H7="Paid","✓",IF(E7="","",IF(TODAY()>E7,TODAY()-E7,"On time"))) -> ✓
A8: INV-004 | B8: Acme Corp | C8: Logo Revisions | D8: 2026-02-01 | E8: 2026-03-02 | F8: 800 | G8: 2026-02-28 | H8: Paid | I8: =IF(H8="Paid","✓",IF(E8="","",IF(TODAY()>E8,TODAY()-E8,"On time"))) -> ✓
A9: INV-005 | B9: Delta Media | C9: Social Strategy | D9: 2026-02-10 | E9: 2026-03-11 | F9: 2200 | H9: Overdue | I9: =IF(H9="Paid","✓",IF(E9="","",IF(TODAY()>E9,TODAY()-E9,"On time"))) -> On time
A10: INV-006 | B10: Beta Startup | C10: Website Phase 2 | D10: 2026-02-25 | E10: 2026-03-26 | F10: 5000 | G10: 2026-03-10 | H10: Paid | I10: =IF(H10="Paid","✓",IF(E10="","",IF(TODAY()>E10,TODAY()-E10,"On time"))) -> ✓
A11: INV-007 | B11: Epsilon Co | C11: Copywriting | D11: 2026-03-01 | E11: 2026-03-31 | F11: 1800 | H11: Pending | I11: =IF(H11="Paid","✓",IF(E11="","",IF(TODAY()>E11,TODAY()-E11,"On time"))) -> On time
A12: INV-008 | B12: Gamma LLC | C12: SEO Mar | D12: 2026-03-15 | E12: 2026-04-14 | F12: 1200 | H12: Pending | I12: =IF(H12="Paid","✓",IF(E12="","",IF(TODAY()>E12,TODAY()-E12,"On time"))) -> On time
A13: INV-009 | B13: Zeta Brands | C13: Marketing | D13: 2026-03-20 | E13: 2026-04-19 | F13: 4500 | H13: Pending | I13: =IF(H13="Paid","✓",IF(E13="","",IF(TODAY()>E13,TODAY()-E13,"On time"))) -> On time
I14: =IF(H14="Paid","✓",IF(E14="","",IF(TODAY()>E14,TODAY()-E14,"On time")))
I15: =IF(H15="Paid","✓",IF(E15="","",IF(TODAY()>E15,TODAY()-E15,"On time")))
I16: =IF(H16="Paid","✓",IF(E16="","",IF(TODAY()>E16,TODAY()-E16,"On time")))
I17: =IF(H17="Paid","✓",IF(E17="","",IF(TODAY()>E17,TODAY()-E17,"On time")))
I18: =IF(H18="Paid","✓",IF(E18="","",IF(TODAY()>E18,TODAY()-E18,"On time")))
I19: =IF(H19="Paid","✓",IF(E19="","",IF(TODAY()>E19,TODAY()-E19,"On time")))
I20: =IF(H20="Paid","✓",IF(E20="","",IF(TODAY()>E20,TODAY()-E20,"On time")))
I21: =IF(H21="Paid","✓",IF(E21="","",IF(TODAY()>E21,TODAY()-E21,"On time")))
I22: =IF(H22="Paid","✓",IF(E22="","",IF(TODAY()>E22,TODAY()-E22,"On time")))
I23: =IF(H23="Paid","✓",IF(E23="","",IF(TODAY()>E23,TODAY()-E23,"On time")))
I24: =IF(H24="Paid","✓",IF(E24="","",IF(TODAY()>E24,TODAY()-E24,"On time")))
I25: =IF(H25="Paid","✓",IF(E25="","",IF(TODAY()>E25,TODAY()-E25,"On time")))
... I53: =IF(H53="Paid","✓",IF(E53="","",IF(TODAY()>E53,TODAY()-E53,"On time")))
A55: INVOICE AGING SUMMARY
A56: Current (not yet due) | F56: =SUMPRODUCT((H5:H53<>"Paid")*(E5:E53>="")*(TODAY()<=E5:E53)*F5:F53) -> 9700
A57: 1–30 Days Overdue | F57: =SUMPRODUCT((H5:H53<>"Paid")*(TODAY()-E5:E53>=1)*(TODAY()-E5:E53<=30)*F5:F53) -> 2200
A58: 31–60 Days Overdue | F58: =SUMPRODUCT((H5:H53<>"Paid")*(TODAY()-E5:E53>=31)*(TODAY()-E5:E53<=60)*F5:F53) -> 0
A59: 60+ Days Overdue (collections?) | F59: =SUMPRODUCT((H5:H53<>"Paid")*(TODAY()-E5:E53>60)*F5:F53) -> 0
A60: Total Collected (Paid) | F60: =SUMIF(H5:H53,"Paid",F5:F53) -> 15500

Sheet 🧮 Tax Tracker
A1: 🧮 TAX ESTIMATOR & QUARTERLY TRACKER
A3: Estimates only — consult a CPA. Updates live as you log income and expenses.
A4: TAX SUMMARY
A5: Gross Income (YTD) | B5: ='💰 Income Log'!F64 -> 25200
A6: Total Deductible Expenses | B6: ='💸 Expenses'!F65 -> 1165.89
A7: Mileage Deduction | B7: ='🚗 Mileage & Home Office'!G52 -> 55.744
A8: Home Office Deduction | B8: ='🚗 Mileage & Home Office'!E62 -> 5300
A9: Total Deductions | B9: =B6+B7+B8 -> 6521.634
A10: NET TAXABLE INCOME | B10: =B5-B9 -> 18678.366
A12: TAX RATES (from Settings)
A13: Federal Rate | B13: ='⚙ Settings'!C11 -> 0.22
A14: State Rate | B14: ='⚙ Settings'!C12 -> 0.08
A15: SE Tax Rate | B15: ='⚙ Settings'!C13 -> 0.153
A17: TAX ESTIMATES
A18: Estimated Federal Tax | B18: =B13*B10 -> 4109.2405
A19: Estimated State Tax | B19: =B14*B10 -> 1494.2693
A20: Estimated SE Tax | B20: =B15*B10 -> 2857.79
A21: TOTAL ESTIMATED TAX | B21: =B18+B19+B20 -> 8461.2998
A22: Effective Tax Rate | B22: =IFERROR(B21/B5,0) -> 0.33576586
A24: TAKE-HOME SUMMARY
A25: Gross Income | B25: =B5 -> 25200
A26: Minus: All Expenses | B26: =-B6 -> -1165.89
A27: Minus: Total Tax | B27: =-B21 -> -8461.2998
A28: ESTIMATED NET TAKE-HOME | B28: =B25+B26+B27 -> 15572.81
A29: Monthly Average Take-Home | B29: =B28/12 -> 1297.7342
A31: QUARTERLY ESTIMATED PAYMENTS
A32: Quarter | B32: Due Date | C32: Est. Tax Due | D32: Amount Paid | E32: Balance Owed
A33: Q1 Jan–Mar | B33: April 15, 2026 | C33: =B21/4 -> 2115.3249 | D33: 0 | E33: =C33-D33 -> 2115.3249
A34: Q2 Apr–Jun | B34: June 15, 2026 | C34: =B21/4 -> 2115.3249 | D34: 0 | E34: =C34-D34 -> 2115.3249
A35: Q3 Jul–Sep | B35: September 15, 2026 | C35: =B21/4 -> 2115.3249 | D35: 0 | E35: =C35-D35 -> 2115.3249
A36: Q4 Oct–Dec | B36: January 15, 2027 | C36: =B21/4 -> 2115.3249 | D36: 0 | E36: =C36-D36 -> 2115.3249

Sheet 👥 Client Report
A1: 👥 CLIENT REPORT — Who's Worth Your Time?
A3: Auto-calculates revenue per client, invoice count, and 1099 alert. Refresh with Ctrl+Alt+F9.
A4: Client Name | B4: Total Billed | C4: # Invoices | D4: Avg Invoice | E4: Paid Total | F4: Outstanding | G4: 1099 Alert
A5: Acme Corp | B5: =SUMIF('💰 Income Log'!B5:B63,A5,'💰 Income Log'!F5:F63) -> 4300 | C5: =COUNTIF('💰 Income Log'!B5:B63,A5) -> 2 | D5: =IFERROR(B5/C5,0) -> 2150 | E5: =SUMPRODUCT(('🧾 Invoices'!B5:B53=A5)*('🧾 Invoices'!H5:H53="Paid")*('🧾 Invoices'!F5:F53)) -> 4300 | F5: =B5-E5 -> 0 | G5: =IF(B5>'⚙ Settings'!C21,"⚠ Expect 1099","—") -> ⚠ Expect 1099
A6: Beta Startup | B6: =SUMIF('💰 Income Log'!B5:B63,A6,'💰 Income Log'!F5:F63) -> 10000 | C6: =COUNTIF('💰 Income Log'!B5:B63,A6) -> 2 | D6: =IFERROR(B6/C6,0) -> 5000 | E6: =SUMPRODUCT(('🧾 Invoices'!B5:B53=A6)*('🧾 Invoices'!H5:H53="Paid")*('🧾 Invoices'!F5:F53)) -> 10000 | F6: =B6-E6 -> 0 | G6: =IF(B6>'⚙ Settings'!C21,"⚠ Expect 1099","—") -> ⚠ Expect 1099
A7: Gamma LLC | B7: =SUMIF('💰 Income Log'!B5:B63,A7,'💰 Income Log'!F5:F63) -> 2400 | C7: =COUNTIF('💰 Income Log'!B5:B63,A7) -> 2 | D7: =IFERROR(B7/C7,0) -> 1200 | E7: =SUMPRODUCT(('🧾 Invoices'!B5:B53=A7)*('🧾 Invoices'!H5:H53="Paid")*('🧾 Invoices'!F5:F53)) -> 1200 | F7: =B7-E7 -> 1200 | G7: =IF(B7>'⚙ Settings'!C21,"⚠ Expect 1099","—") -> ⚠ Expect 1099
A8: Delta Media | B8: =SUMIF('💰 Income Log'!B5:B63,A8,'💰 Income Log'!F5:F63) -> 2200 | C8: =COUNTIF('💰 Income Log'!B5:B63,A8) -> 1 | D8: =IFERROR(B8/C8,0) -> 2200 | E8: =SUMPRODUCT(('🧾 Invoices'!B5:B53=A8)*('🧾 Invoices'!H5:H53="Paid")*('🧾 Invoices'!F5:F53)) -> 0 | F8: =B8-E8 -> 2200 | G8: =IF(B8>'⚙ Settings'!C21,"⚠ Expect 1099","—") -> ⚠ Expect 1099
A9: Epsilon Co | B9: =SUMIF('💰 Income Log'!B5:B63,A9,'💰 Income Log'!F5:F63) -> 1800 | C9: =COUNTIF('💰 Income Log'!B5:B63,A9) -> 1 | D9: =IFERROR(B9/C9,0) -> 1800 | E9: =SUMPRODUCT(('🧾 Invoices'!B5:B53=A9)*('🧾 Invoices'!H5:H53="Paid")*('🧾 Invoices'!F5:F53)) -> 0 | F9: =B9-E9 -> 1800 | G9: =IF(B9>'⚙ Settings'!C21,"⚠ Expect 1099","—") -> ⚠ Expect 1099
A10: Zeta Brands | B10: =SUMIF('💰 Income Log'!B5:B63,A10,'💰 Income Log'!F5:F63) -> 4500 | C10: =COUNTIF('💰 Income Log'!B5:B63,A10) -> 1 | D10: =IFERROR(B10/C10,0) -> 4500 | E10: =SUMPRODUCT(('🧾 Invoices'!B5:B53=A10)*('🧾 Invoices'!H5:H53="Paid")*('🧾 Invoices'!F5:F53)) -> 0 | F10: =B10-E10 -> 4500 | G10: =IF(B10>'⚙ Settings'!C21,"⚠ Expect 1099","—") -> ⚠ Expect 1099
B11: =IF(A11="","",SUMIF('💰 Income Log'!B5:B63,A11,'💰 Income Log'!F5:F63)) | C11: =IF(A11="","",COUNTIF('💰 Income Log'!B5:B63,A11)) | D11: =IFERROR(B11/C11,"") | E11: =IF(A11="","",SUMPRODUCT(('🧾 Invoices'!B5:B53=A11)*('🧾 Invoices'!H5:H53="Paid")*('🧾 Invoices'!F5:F53))) | F11: =IF(A11="","",B11-E11) | G11: =IF(A11="","",IF(B11>'⚙ Settings'!C21,"⚠ Expect 1099","—"))
B12: =IF(A12="","",SUMIF('💰 Income Log'!B5:B63,A12,'💰 Income Log'!F5:F63)) | C12: =IF(A12="","",COUNTIF('💰 Income Log'!B5:B63,A12)) | D12: =IFERROR(B12/C12,"") | E12: =IF(A12="","",SUMPRODUCT(('🧾 Invoices'!B5:B53=A12)*('🧾 Invoices'!H5:H53="Paid")*('🧾 Invoices'!F5:F53))) | F12: =IF(A12="","",B12-E12) | G12: =IF(A12="","",IF(B12>'⚙ Settings'!C21,"⚠ Expect 1099","—"))
B13: =IF(A13="","",SUMIF('💰 Income Log'!B5:B63,A13,'💰 Income Log'!F5:F63)) | C13: =IF(A13="","",COUNTIF('💰 Income Log'!B5:B63,A13)) | D13: =IFERROR(B13/C13,"") | E13: =IF(A13="","",SUMPRODUCT(('🧾 Invoices'!B5:B53=A13)*('🧾 Invoices'!H5:H53="Paid")*('🧾 Invoices'!F5:F53))) | F13: =IF(A13="","",B13-E13) | G13: =IF(A13="","",IF(B13>'⚙ Settings'!C21,"⚠ Expect 1099","—"))
B14: =IF(A14="","",SUMIF('💰 Income Log'!B5:B63,A14,'💰 Income Log'!F5:F63)) | C14: =IF(A14="","",COUNTIF('💰 Income Log'!B5:B63,A14)) | D14: =IFERROR(B14/C14,"") | E14: =IF(A14="","",SUMPRODUCT(('🧾 Invoices'!B5:B53=A14)*('🧾 Invoices'!H5:H53="Paid")*('🧾 Invoices'!F5:F53))) | F14: =IF(A14="","",B14-E14) | G14: =IF(A14="","",IF(B14>'⚙ Settings'!C21,"⚠ Expect 1099","—"))
B15: =IF(A15="","",SUMIF('💰 Income Log'!B5:B63,A15,'💰 Income Log'!F5:F63)) | C15: =IF(A15="","",COUNTIF('💰 Income Log'!B5:B63,A15)) | D15: =IFERROR(B15/C15,"") | E15: =IF(A15="","",SUMPRODUCT(('🧾 Invoices'!B5:B53=A15)*('🧾 Invoices'!H5:H53="Paid")*('🧾 Invoices'!F5:F53))) | F15: =IF(A15="","",B15-E15) | G15: =IF(A15="","",IF(B15>'⚙ Settings'!C21,"⚠ Expect 1099","—"))
B16: =IF(A16="","",SUMIF('💰 Income Log'!B5:B63,A16,'💰 Income Log'!F5:F63)) | C16: =IF(A16="","",COUNTIF('💰 Income Log'!B5:B63,A16)) | D16: =IFERROR(B16/C16,"") | E16: =IF(A16="","",SUMPRODUCT(('🧾 Invoices'!B5:B53=A16)*('🧾 Invoices'!H5:H53="Paid")*('🧾 Invoices'!F5:F53))) | F16: =IF(A16="","",B16-E16) | G16: =IF(A16="","",IF(B16>'⚙ Settings'!C21,"⚠ Expect 1099","—"))
B17: =IF(A17="","",SUMIF('💰 Income Log'!B5:B63,A17,'💰 Income Log'!F5:F63)) | C17: =IF(A17="","",COUNTIF('💰 Income Log'!B5:B63,A17)) | D17: =IFERROR(B17/C17,"") | E17: =IF(A17="","",SUMPRODUCT(('🧾 Invoices'!B5:B53=A17)*('🧾 Invoices'!H5:H53="Paid")*('🧾 Invoices'!F5:F53))) | F17: =IF(A17="","",B17-E17) | G17: =IF(A17="","",IF(B17>'⚙ Settings'!C21,"⚠ Expect 1099","—"))
B18: =IF(A18="","",SUMIF('💰 Income Log'!B5:B63,A18,'💰 Income Log'!F5:F63)) | C18: =IF(A18="","",COUNTIF('💰 Income Log'!B5:B63,A18)) | D18: =IFERROR(B18/C18,"") | E18: =IF(A18="","",SUMPRODUCT(('🧾 Invoices'!B5:B53=A18)*('🧾 Invoices'!H5:H53="Paid")*('🧾 Invoices'!F5:F53))) | F18: =IF(A18="","",B18-E18) | G18: =IF(A18="","",IF(B18>'⚙ Settings'!C21,"⚠ Expect 1099","—"))
B19: =IF(A19="","",SUMIF('💰 Income Log'!B5:B63,A19,'💰 Income Log'!F5:F63)) | C19: =IF(A19="","",COUNTIF('💰 Income Log'!B5:B63,A19)) | D19: =IFERROR(B19/C19,"") | E19: =IF(A19="","",SUMPRODUCT(('🧾 Invoices'!B5:B53=A19)*('🧾 Invoices'!H5:H53="Paid")*('🧾 Invoices'!F5:F53))) | F19: =IF(A19="","",B19-E19) | G19: =IF(A19="","",IF(B19>'⚙ Settings'!C21,"⚠ Expect 1099","—"))
B20: =IF(A20="","",SUMIF('💰 Income Log'!B5:B63,A20,'💰 Income Log'!F5:F63)) | C20: =IF(A20="","",COUNTIF('💰 Income Log'!B5:B63,A20)) | D20: =IFERROR(B20/C20,"") | E20: =IF(A20="","",SUMPRODUCT(('🧾 Invoices'!B5:B53=A20)*('🧾 Invoices'!H5:H53="Paid")*('🧾 Invoices'!F5:F53))) | F20: =IF(A20="","",B20-E20) | G20: =IF(A20="","",IF(B20>'⚙ Settings'!C21,"⚠ Expect 1099","—"))

Sheet 💡 Rate Calculator
A1: 💡 WHAT SHOULD I CHARGE? Rate Calculator
A3: Enter your goals → get your minimum viable rate. Never undercharge again.
B4: YOUR GOALS
B5: Target Annual Take-Home | C5: ='⚙ Settings'!C19 -> 72000 | D5: From Settings
B6: Total Tax Rate (est.) | C6: ='⚙ Settings'!C11+'⚙ Settings'!C12+'⚙ Settings'!C13 -> 0.453 | D6: Federal+State+SE
B7: Gross Income Needed | C7: =C5/(1-C6) -> 131627.06 | D7: Take-home ÷ (1−tax rate)
B8: Annual Business Expenses (est.) | C8: ='💸 Expenses'!F64 -> 1165.89 | D8: From Expense Log
B9: TOTAL REVENUE NEEDED | C9: =C7+C8 -> 132792.95
B11: YOUR TIME
B12: Billable Hours per Week | C12: ='⚙ Settings'!C20 -> 30 | D12: From Settings
B13: Weeks Off per Year | C13: 4 | D13: Vacation + holidays
B14: Billable Weeks per Year | C14: =52-C13 -> 48
B15: TOTAL BILLABLE HOURS/YEAR | C15: =C12*C14 -> 1440
B17: YOUR MINIMUM RATES
B18: Minimum Hourly Rate | C18: =IFERROR(C9/C15,0) -> 92.217324 | D18: Break-even rate
B19: Add 20% cushion | C19: =C18*1.2 -> 110.66079 | D19: Recommended floor
B20: Add 40% cushion | C20: =C18*1.4 -> 129.10425 | D20: Comfortable rate
B22: PROJECT RATE ESTIMATOR
B23: Estimated Hours for Project | C23: 40 | D23: ← Change this
B24: Your Target Hourly Rate | C24: =C19 -> 110.66079 | D24: ← Or override
B25: PROJECT MINIMUM PRICE | C25: =C23*C24 -> 4426.4316
